An error occurred
2016-06-27 16:48:42,043 ERROR: An error occurred [in entry.py:18]
2016-06-27 16:56:20,897 WARNING: An error occurred [in entry.py:18]
[2016-06-27 17:20:55,079] [WARNING]:  * Debugger is active! [in /data0/python/venv/lib/python3.4/site-packages/werkzeug/_internal.py:87]
[2016-06-27 17:21:43,635] [WARNING]:  * Debugger is active! [in /data0/python/venv/lib/python3.4/site-packages/werkzeug/_internal.py:87]
[2016-06-27 17:23:41,300] [WARNING]:  * Debugger is active! [in /data0/python/venv/lib/python3.4/site-packages/werkzeug/_internal.py:87]
[2016-06-27 17:27:27,998] [WARNING]:  * Debugger is active! [in /data0/python/venv/lib/python3.4/site-packages/werkzeug/_internal.py:87]
[2016-06-27 17:54:15,732] [ERROR]: An error occurred [in entry.py:19]
[2016-07-13 20:44:51,189] [ERROR]: Exception on /dafasdfsdf [GET] [in /data0/python/venv/lib/python3.4/site-packages/flask/app.py:1587]
Traceback (most recent call last):
  File "/data0/python/venv/lib/python3.4/site-packages/flask/app.py", line 1639, in full_dispatch_request
    rv = self.dispatch_request()
  File "/data0/python/venv/lib/python3.4/site-packages/flask/app.py", line 1617, in dispatch_request
    self.raise_routing_exception(req)
  File "/data0/python/venv/lib/python3.4/site-packages/flask/app.py", line 1600, in raise_routing_exception
    raise request.routing_exception
  File "/data0/python/venv/lib/python3.4/site-packages/flask/ctx.py", line 294, in match_request
    self.url_adapter.match(return_rule=True)
  File "/data0/python/venv/lib/python3.4/site-packages/werkzeug/routing.py", line 1563, in match
    raise NotFound()
werkzeug.exceptions.NotFound: 404: Not Found

During handling of the above exception, another exception occurred:

Traceback (most recent call last):
  File "/data0/python/venv/lib/python3.4/site-packages/flask/app.py", line 1988, in wsgi_app
    response = self.full_dispatch_request()
  File "/data0/python/venv/lib/python3.4/site-packages/flask/app.py", line 1641, in full_dispatch_request
    rv = self.handle_user_exception(e)
  File "/data0/python/venv/lib/python3.4/site-packages/flask/app.py", line 1539, in handle_user_exception
    return self.handle_http_exception(e)
  File "/data0/python/venv/lib/python3.4/site-packages/flask/app.py", line 1498, in handle_http_exception
    return handler(e)
  File "entry.py", line 26, in page_not_found
    return render_template('404.html'), 404
NameError: name 'render_template' is not defined
[2016-07-13 20:44:56,558] [ERROR]: Exception on /favicon.ico [GET] [in /data0/python/venv/lib/python3.4/site-packages/flask/app.py:1587]
Traceback (most recent call last):
  File "/data0/python/venv/lib/python3.4/site-packages/flask/app.py", line 1639, in full_dispatch_request
    rv = self.dispatch_request()
  File "/data0/python/venv/lib/python3.4/site-packages/flask/app.py", line 1617, in dispatch_request
    self.raise_routing_exception(req)
  File "/data0/python/venv/lib/python3.4/site-packages/flask/app.py", line 1600, in raise_routing_exception
    raise request.routing_exception
  File "/data0/python/venv/lib/python3.4/site-packages/flask/ctx.py", line 294, in match_request
    self.url_adapter.match(return_rule=True)
  File "/data0/python/venv/lib/python3.4/site-packages/werkzeug/routing.py", line 1563, in match
    raise NotFound()
werkzeug.exceptions.NotFound: 404: Not Found

During handling of the above exception, another exception occurred:

Traceback (most recent call last):
  File "/data0/python/venv/lib/python3.4/site-packages/flask/app.py", line 1988, in wsgi_app
    response = self.full_dispatch_request()
  File "/data0/python/venv/lib/python3.4/site-packages/flask/app.py", line 1641, in full_dispatch_request
    rv = self.handle_user_exception(e)
  File "/data0/python/venv/lib/python3.4/site-packages/flask/app.py", line 1539, in handle_user_exception
    return self.handle_http_exception(e)
  File "/data0/python/venv/lib/python3.4/site-packages/flask/app.py", line 1498, in handle_http_exception
    return handler(e)
  File "entry.py", line 26, in page_not_found
    return render_template('404.html'), 404
NameError: name 'render_template' is not defined
[2016-07-13 20:46:32,364] [ERROR]: Exception on / [GET] [in /data0/python/venv/lib/python3.4/site-packages/flask/app.py:1587]
Traceback (most recent call last):
  File "/data0/python/venv/lib/python3.4/site-packages/flask/app.py", line 1988, in wsgi_app
    response = self.full_dispatch_request()
  File "/data0/python/venv/lib/python3.4/site-packages/flask/app.py", line 1642, in full_dispatch_request
    response = self.make_response(rv)
  File "/data0/python/venv/lib/python3.4/site-packages/flask/app.py", line 1746, in make_response
    rv = self.response_class.force_type(rv, request.environ)
  File "/data0/python/venv/lib/python3.4/site-packages/werkzeug/wrappers.py", line 847, in force_type
    response = BaseResponse(*_run_wsgi_app(response, environ))
  File "/data0/python/venv/lib/python3.4/site-packages/werkzeug/wrappers.py", line 57, in _run_wsgi_app
    return _run_wsgi_app(*args)
  File "/data0/python/venv/lib/python3.4/site-packages/werkzeug/test.py", line 871, in run_wsgi_app
    app_rv = app(environ, start_response)
TypeError: 'int' object is not callable
[2016-07-13 20:46:34,103] [ERROR]: Exception on /favicon.ico [GET] [in /data0/python/venv/lib/python3.4/site-packages/flask/app.py:1587]
Traceback (most recent call last):
  File "/data0/python/venv/lib/python3.4/site-packages/flask/app.py", line 1639, in full_dispatch_request
    rv = self.dispatch_request()
  File "/data0/python/venv/lib/python3.4/site-packages/flask/app.py", line 1617, in dispatch_request
    self.raise_routing_exception(req)
  File "/data0/python/venv/lib/python3.4/site-packages/flask/app.py", line 1600, in raise_routing_exception
    raise request.routing_exception
  File "/data0/python/venv/lib/python3.4/site-packages/flask/ctx.py", line 294, in match_request
    self.url_adapter.match(return_rule=True)
  File "/data0/python/venv/lib/python3.4/site-packages/werkzeug/routing.py", line 1563, in match
    raise NotFound()
werkzeug.exceptions.NotFound: 404: Not Found

During handling of the above exception, another exception occurred:

Traceback (most recent call last):
  File "/data0/python/venv/lib/python3.4/site-packages/flask/app.py", line 1988, in wsgi_app
    response = self.full_dispatch_request()
  File "/data0/python/venv/lib/python3.4/site-packages/flask/app.py", line 1641, in full_dispatch_request
    rv = self.handle_user_exception(e)
  File "/data0/python/venv/lib/python3.4/site-packages/flask/app.py", line 1539, in handle_user_exception
    return self.handle_http_exception(e)
  File "/data0/python/venv/lib/python3.4/site-packages/flask/app.py", line 1498, in handle_http_exception
    return handler(e)
  File "entry.py", line 30, in page_not_found
    return render_template('404.html'), 404
NameError: name 'render_template' is not defined
[2016-07-13 20:46:44,587] [ERROR]: Exception on / [GET] [in /data0/python/venv/lib/python3.4/site-packages/flask/app.py:1587]
Traceback (most recent call last):
  File "/data0/python/venv/lib/python3.4/site-packages/flask/app.py", line 1988, in wsgi_app
    response = self.full_dispatch_request()
  File "/data0/python/venv/lib/python3.4/site-packages/flask/app.py", line 1642, in full_dispatch_request
    response = self.make_response(rv)
  File "/data0/python/venv/lib/python3.4/site-packages/flask/app.py", line 1746, in make_response
    rv = self.response_class.force_type(rv, request.environ)
  File "/data0/python/venv/lib/python3.4/site-packages/werkzeug/wrappers.py", line 847, in force_type
    response = BaseResponse(*_run_wsgi_app(response, environ))
  File "/data0/python/venv/lib/python3.4/site-packages/werkzeug/test.py", line 871, in run_wsgi_app
    app_rv = app(environ, start_response)
TypeError: 'int' object is not callable
[2016-07-13 20:46:45,947] [ERROR]: Exception on /favicon.ico [GET] [in /data0/python/venv/lib/python3.4/site-packages/flask/app.py:1587]
Traceback (most recent call last):
  File "/data0/python/venv/lib/python3.4/site-packages/flask/app.py", line 1639, in full_dispatch_request
    rv = self.dispatch_request()
  File "/data0/python/venv/lib/python3.4/site-packages/flask/app.py", line 1617, in dispatch_request
    self.raise_routing_exception(req)
  File "/data0/python/venv/lib/python3.4/site-packages/flask/app.py", line 1600, in raise_routing_exception
    raise request.routing_exception
  File "/data0/python/venv/lib/python3.4/site-packages/flask/ctx.py", line 294, in match_request
    self.url_adapter.match(return_rule=True)
  File "/data0/python/venv/lib/python3.4/site-packages/werkzeug/routing.py", line 1563, in match
    raise NotFound()
werkzeug.exceptions.NotFound: 404: Not Found

During handling of the above exception, another exception occurred:

Traceback (most recent call last):
  File "/data0/python/venv/lib/python3.4/site-packages/flask/app.py", line 1988, in wsgi_app
    response = self.full_dispatch_request()
  File "/data0/python/venv/lib/python3.4/site-packages/flask/app.py", line 1641, in full_dispatch_request
    rv = self.handle_user_exception(e)
  File "/data0/python/venv/lib/python3.4/site-packages/flask/app.py", line 1539, in handle_user_exception
    return self.handle_http_exception(e)
  File "/data0/python/venv/lib/python3.4/site-packages/flask/app.py", line 1498, in handle_http_exception
    return handler(e)
  File "entry.py", line 30, in page_not_found
    return render_template('404.html'), 404
NameError: name 'render_template' is not defined
[2016-07-13 20:50:12,305] [ERROR]: Exception on / [GET] [in /data0/python/venv/lib/python3.4/site-packages/flask/app.py:1587]
Traceback (most recent call last):
  File "/data0/python/venv/lib/python3.4/site-packages/flask/app.py", line 1988, in wsgi_app
    response = self.full_dispatch_request()
  File "/data0/python/venv/lib/python3.4/site-packages/flask/app.py", line 1642, in full_dispatch_request
    response = self.make_response(rv)
  File "/data0/python/venv/lib/python3.4/site-packages/flask/app.py", line 1746, in make_response
    rv = self.response_class.force_type(rv, request.environ)
  File "/data0/python/venv/lib/python3.4/site-packages/werkzeug/wrappers.py", line 847, in force_type
    response = BaseResponse(*_run_wsgi_app(response, environ))
  File "/data0/python/venv/lib/python3.4/site-packages/werkzeug/wrappers.py", line 57, in _run_wsgi_app
    return _run_wsgi_app(*args)
  File "/data0/python/venv/lib/python3.4/site-packages/werkzeug/test.py", line 871, in run_wsgi_app
    app_rv = app(environ, start_response)
TypeError: 'int' object is not callable
[2016-07-13 20:50:13,638] [ERROR]: Exception on /favicon.ico [GET] [in /data0/python/venv/lib/python3.4/site-packages/flask/app.py:1587]
Traceback (most recent call last):
  File "/data0/python/venv/lib/python3.4/site-packages/flask/app.py", line 1639, in full_dispatch_request
    rv = self.dispatch_request()
  File "/data0/python/venv/lib/python3.4/site-packages/flask/app.py", line 1617, in dispatch_request
    self.raise_routing_exception(req)
  File "/data0/python/venv/lib/python3.4/site-packages/flask/app.py", line 1600, in raise_routing_exception
    raise request.routing_exception
  File "/data0/python/venv/lib/python3.4/site-packages/flask/ctx.py", line 294, in match_request
    self.url_adapter.match(return_rule=True)
  File "/data0/python/venv/lib/python3.4/site-packages/werkzeug/routing.py", line 1563, in match
    raise NotFound()
werkzeug.exceptions.NotFound: 404: Not Found

During handling of the above exception, another exception occurred:

Traceback (most recent call last):
  File "/data0/python/venv/lib/python3.4/site-packages/flask/app.py", line 1988, in wsgi_app
    response = self.full_dispatch_request()
  File "/data0/python/venv/lib/python3.4/site-packages/flask/app.py", line 1641, in full_dispatch_request
    rv = self.handle_user_exception(e)
  File "/data0/python/venv/lib/python3.4/site-packages/flask/app.py", line 1539, in handle_user_exception
    return self.handle_http_exception(e)
  File "/data0/python/venv/lib/python3.4/site-packages/flask/app.py", line 1498, in handle_http_exception
    return handler(e)
  File "entry.py", line 30, in page_not_found
    return render_template('404.html'), 404
  File "/data0/python/venv/lib/python3.4/site-packages/flask/templating.py", line 133, in render_template
    return _render(ctx.app.jinja_env.get_or_select_template(template_name_or_list),
  File "/data0/python/venv/lib/python3.4/site-packages/jinja2/environment.py", line 851, in get_or_select_template
    return self.get_template(template_name_or_list, parent, globals)
  File "/data0/python/venv/lib/python3.4/site-packages/jinja2/environment.py", line 812, in get_template
    return self._load_template(name, self.make_globals(globals))
  File "/data0/python/venv/lib/python3.4/site-packages/jinja2/environment.py", line 774, in _load_template
    cache_key = self.loader.get_source(self, name)[1]
  File "/data0/python/venv/lib/python3.4/site-packages/flask/templating.py", line 57, in get_source
    return self._get_source_fast(environment, template)
  File "/data0/python/venv/lib/python3.4/site-packages/flask/templating.py", line 85, in _get_source_fast
    raise TemplateNotFound(template)
jinja2.exceptions.TemplateNotFound: 404.html
[2016-07-13 20:50:39,589] [ERROR]: Exception on / [GET] [in /data0/python/venv/lib/python3.4/site-packages/flask/app.py:1587]
Traceback (most recent call last):
  File "/data0/python/venv/lib/python3.4/site-packages/flask/app.py", line 1988, in wsgi_app
    response = self.full_dispatch_request()
  File "/data0/python/venv/lib/python3.4/site-packages/flask/app.py", line 1642, in full_dispatch_request
    response = self.make_response(rv)
  File "/data0/python/venv/lib/python3.4/site-packages/flask/app.py", line 1746, in make_response
    rv = self.response_class.force_type(rv, request.environ)
  File "/data0/python/venv/lib/python3.4/site-packages/werkzeug/wrappers.py", line 847, in force_type
    response = BaseResponse(*_run_wsgi_app(response, environ))
  File "/data0/python/venv/lib/python3.4/site-packages/werkzeug/wrappers.py", line 57, in _run_wsgi_app
    return _run_wsgi_app(*args)
  File "/data0/python/venv/lib/python3.4/site-packages/werkzeug/test.py", line 871, in run_wsgi_app
    app_rv = app(environ, start_response)
TypeError: 'int' object is not callable
